Workbook

Sheet Overview
B2: Safety-Aware Elevation of Privilege — Consolidated Workshop Results
B3: Raw threat outputs from the EoP game sessions (Sechi & Saad Noori, SecAssure 2026).
B5: Session inventory
B6: Session | C6: Participants | D6: Date | E6: # threats | F6: Recording
B7: A — Conf. workshop | C7: Researchers / academics at a Norwegian Cybersecurity Conference Workshop — 4 teams (Leonardo, Donatello, Michelangelo, Raphael) | D7: 24 Nov 2025 | E7: 11 | F7: Online platform + facilitator notes
B8: B — CTF group | C8: A university cybersecurity capture-the-flag group — seven students in three pairs (binômes), recorded as Students A, B, C | D8: 6 Feb 2026 | E8: 16 | F8: Online platform + facilitator notes
B9: C — Master students | C9: University master students — Group A & Group B | D9: 25 Feb 2026 | E9: 2 threats tagged (7 entries) | F9: Paper table + cards + facilitator notes
B10: A 3-threat platform tutorial demo (24 Nov) was excluded as non-data. Facilitator notes were kept for all three sessions. Identifying details are anonymised: student names as Student A–H, and the conference teams as fantasy names (Leonardo, Donatello, Michelangelo, Raphael).
B12: What the columns mean
B14: Cyber severity (High/Medium/Low) | C14: The threat's information-security impact — confidentiality, integrity, availability — rated during EoP play. The security axis of the game; NOT the physical/safety consequence.
B15: Safety/HSE impact (High/Medium/Low) | C15: The physical / health-safety-environment consequence if the threat succeeds (modification M3). Independent of cyber severity.
B16: High | C16: Direct risk of injury, major outage, severe equipment damage, environmental impact.
B17: Medium | C17: Contributes to unsafe conditions (loss of operator visibility, delayed response, weakened protection).
B18: Low / None | C18: Mainly financial, reputational or confidentiality impact; no plausible path to a physical hazard.
B20: Note on Mitigation: discussing mitigations was deliberately out of scope in these sessions — the focus was the Safety/HSE impact dimension — so only a few were recorded. In EoP a mitigation addresses the underlying cybersecurity threat (the STRIDE vulnerability) by design, not the safety impact directly; reducing the cyber threat is what lowers the safety consequence.
B22: All values are recorded data. Cyber severity (Sessions A & B) is from the platform; Safety/HSE impact (Session C) is from the participant groups; and the Safety/HSE impact (A & B) and Cyber severity (C) are confirmed from the facilitator's session notes — see the 'Facilitator notes' sheet for the per-threat reasoning.

Sheet All Threats
A1: Session | B1: No. | C1: Threat name | D1: STRIDE | E1: Cyber severity | F1: Author / group | G1: Description | H1: Mitigation | I1: Device / connection link | J1: Safety/HSE impact | K1: Safety reasoning
A2: A — Conf. workshop | B2: 1 | C2: OT network layer tampering | D2: Tampering | E2: High | F2: Table 2: Donatello | G2: Modify the build system and produce signed builds, reaching the process/OT network layer. | I2: Process / OT network layer | J2: High | K2: This reaches the OT/process layer directly, so the link to physical process impact is clear.
A3: A — Conf. workshop | B3: 2 | C3: Insert a backdoor in the SCADA HMI | D3: Tampering | E3: Medium | F3: Table 3: Michelangelo | G3: Modify the build system and produce signed builds. | I3: SCADA HMI | J3: Medium | K3: The HMI mainly affects supervision and operator trust. It becomes safety-critical if it leads to wrong decisions, but it is not direct actuation by itself.
A4: A — Conf. workshop | B4: 3 | C4: VPN key | D4: Tampering | E4: Medium | F4: Table 4: Raphael | G4: Use the custom key to access VPN remote access. | I4: VPN remote access | J4: Medium | K4: A VPN key is mainly an access path into the SCADA environment. The safety impact depends on what the attacker can reach after that.
A5: A — Conf. workshop | B5: 4 | C5: Backdoor (MTU) | D5: Tampering | E5: High | F5: Table 1: Leonardo | G5: MTU backdoor: change safety features, raise allowed operating temperatures / max volts to cause physical wear and tear. | H5: Code-scanning tool to verify expected behaviour. | I5: MTU | J5: High | K5: The MTU is close to process control, so a backdoor could affect commands, limits, or process behaviour.
A6: A — Conf. workshop | B6: 5 | C6: Replaying of commands between RTU and IED | D6: Tampering | E6: High | F6: Table 3: Michelangelo | G6: Replay commands sent to the IED to cause unexpected physical behaviour. | I6: RTU ↔ IED | J6: High | K6: Replayed commands on this path can trigger unintended field actions, so the safety link is direct.
A7: A — Conf. workshop | B7: 6 | C7: MTU data tampering | D7: Tampering | E7: High | F7: Table 4: Raphael | G7: Manipulate MTU sensor data/logs to damage the system. | I7: MTU | J7: High | K7: False MTU data can make operators act on an incorrect process state, which may lead to unsafe operation or equipment damage.
A8: A — Conf. workshop | B8: 7 | C8: SCADA HMI tampering | D8: Tampering | E8: Medium | F8: Table 2: Donatello | G8: Replay incorrect values on the SCADA HMI. | I8: SCADA HMI | J8: Medium | K8: This mainly affects what operators see and trust. The safety impact is indirect unless control actions are also affected.
A9: A — Conf. workshop | B9: 8 | C9: Displaying old data | D9: Tampering | E9: Medium | F9: Table 1: Leonardo | G9: Feed the MTU outdated historical data so a future attack is not discovered as quickly. | I9: MTU | J9: Medium | K9: Stale data can delay detection and response. The risk is serious, but it works through loss of visibility rather than direct control.
A10: A — Conf. workshop | B10: 9 | C10: Create information blindness | D10: Tampering | E10: High | F10: Table 1: Leonardo | G10: Clone sensors with fake virtual ones; the system loses data from the 'ghost' segment so attacks and safety hazards needing operator input go unnoticed. | I10: Field sensors | J10: High | K10: If operators or protection functions lose visibility of part of the process, hazards may go unnoticed.
A11: A — Conf. workshop | B11: 10 | C11: MTU safety-parameter tampering | D11: Tampering | E11: High | F11: Table 2: Donatello | G11: Tamper with limits/alerts for PLC safety events. | I11: MTU / PLC safety parameters | J11: High | K11: Changing safety parameters directly weakens or bypasses a protection layer.
A12: A — Conf. workshop | B12: 11 | C12: Attack via physical device (USB) | D12: Tampering | E12: Medium | F12: Table 4: Raphael | G12: Malicious USB in the HMI workstation runs a payload to gain access, execute code, and manipulate displayed process data. | I12: HMI workstation | J12: Medium | K12: A USB attack is an entry point. It becomes high only if the compromise reaches process control or safety-related functions.
A13: B — CTF group | B13: 1 | C13: Tampering (SCADA Server) | D13: Tampering | E13: Medium | F13: Student A | G13: Modify the build system and produce signed builds. Tampering the SCADA Server. | I13: SCADA Server | J13: High | K13: Treated as high if the SCADA server can be manipulated, because it may affect supervision, commands, and the path toward OT control.
A14: B — CTF group | B14: 2 | C14: Tampering the DES | D14: Tampering | E14: Medium | F14: Student B | G14: No integrity protection; send false alerts to the DES to throw operators off. | I14: Data Exchange Server (DES) | J14: Low–Medium | K14: The DES can mislead operators or disturb data exchange, but the safety link is indirect unless it changes operational decisions or enables deeper SCADA access.
A15: B — CTF group | B15: 3 | C15: DMZ Firewall | D15: Tampering | E15: High | F15: Student C | G15: Modify firewall rules to allow access to the SCADA network that should be limited to the DMZ. | I15: DMZ Firewall | J15: Medium–High | K15: The firewall itself is not the hazard. The safety impact becomes high if rule changes open a path from IT/DMZ into SCADA or OT.
A16: B — CTF group | B16: 4 | C16: Router | D16: Tampering | E16: Medium | F16: Student B | G16: Tamper with the router to reroute packets and eavesdrop. | I16: Router / Office network | J16: Low–Medium | K16: A good example of the CTF group focusing on familiar IT. An office router is not automatically safety-critical unless it carries SCADA or OT traffic.
A17: B — CTF group | B17: 5 | C17: VPN firewall | D17: Tampering | E17: Medium | F17: Student C | G17: Load code via an extension point; loosen restrictions on the VPN connection to SCADA. | I17: VPN Firewall / SCADA | J17: Medium | K17: Weak VPN controls make access easier, but the safety impact depends on whether that access can reach SCADA or OT functions.
... A23: B — CTF group | B23: 11 | C23: Spoofing VPN | D23: Spoofing | E23: Medium | F23: Student C | G23: Gives access to the SCADA network. | I23: VPN | J23: Medium | K23: VPN spoofing is not the safety impact itself. It matters because it may create access to SCADA or OT.
A24: B — CTF group | B24: 12 | C24: Credibility | D24: Spoofing | E24: High | F24: Student A | G24: Hijack the JWT via XSS on a vulnerable company site, then traverse it with those credentials. | H24: Encrypt credentials. | I24: Company web app / JWT | J24: Low | K24: Mainly IT-focused: identity, trust, web security, or confidentiality. There is no clear physical process path.
A25: B — CTF group | B25: 13 | C25: Data Exchange server | D25: Spoofing | E25: High | F25: Student B | G25: Steal credentials stored on the server (e.g. world-readable key) and reuse them to bypass login. | I25: Data Exchange Server | J25: Low–Medium | K25: DES compromise may support later access or wrong information flow, but the safety effect is indirect unless operational data is altered.
A26: B — CTF group | B26: 14 | C26: Attack the router | D26: Spoofing | E26: High | F26: Student B | G26: Reverse-access the DES and office workstation to map the system as an operator would. | I26: Router / DES / workstation | J26: Low–Medium | K26: Reconnaissance or router attacks can support later compromise, but they do not by themselves create physical harm.
A27: B — CTF group | B27: 15 | C27: DDoS for opening gateways | D27: Denial of Service | E27: High | F27: Student A | G27: A DDoS could make servers unresponsive and expose infrastructure vulnerabilities. | I27: Servers / gateways | J27: Medium–High | K27: Availability loss can become safety-relevant if operators lose monitoring or control during an abnormal process condition.
A28: B — CTF group | B28: 16 | C28: Elevate from the workstations to the SCADA server | D28: Elevation of Privilege | E28: High | F28: Student B | G28: Spoof the workstation and then elevate to the SCADA server. | I28: Workstation → SCADA Server | J28: High | K28: The key IT-to-OT escalation path. Once the attack reaches the SCADA server, the safety link becomes strong.
A29: C — Master students | B29: 1 | C29: Tampering 5 | D29: Tampering | E29: High | F29: Group A (Student D, Student E, Student F) | G29: Safety tagging — Round 1 | I29: SCADA Servers — SCADA Network | J29: High | K29: SCADA servers lack encryption, so they are susceptible to tampering/interception; recorded-then-reused credentials make severity High. Servers hold many process data points and company-sensitive production info; can severely impact production.
A30: C — Master students | B30: 2 | C30: Tampering 5 (legacy access) | D30: Tampering | E30: Medium | F30: Group A (Student D, Student E, Student F) | G30: Safety tagging — Round 1 | I30: Office Network | J30: Low | K30: Occurs if the attacker has user authentication; weakness from legacy configs giving access to the shared folder. Impact could grow via unauthorised document/data leakage.
A31: C — Master students | B31: 3 | C31: EoP 4 | D31: Elevation of Privilege | E31: High | F31: Group A (Student D, Student E, Student F) | G31: Safety tagging — Round 2 | I31: SCADA Server — SCADA Network | J31: High | K31: Privileges elevated from a closed environment to the SCADA server; if it is the server, the attacker can hold admin rights.
A32: C — Master students | B32: 4 | C32: EoP 4 | D32: Elevation of Privilege | E32: High | F32: Group A (Student D, Student E, Student F) | G32: Safety tagging — Round 2 | I32: OT Network | J32: High | K32: If reached (difficult), the attacker interacts directly with physical assets via IEDs, RTUs and MV/LV bus systems. Impact: physical damage, safety hazards, or complete shutdown.
A33: C — Master students | B33: 5 | C33: EoP 4 (office elevation) | D33: Elevation of Privilege | E33: Medium | F33: Group A (Student D, Student E, Student F) | G33: Safety tagging — Round 2 | I33: Office Network | J33: Low–Medium | K33: Initial access to an office workstation gives a foothold; the attacker can attempt to elevate and roam to hidden confidential information.
A34: C — Master students | B34: 6 | C34: Tampering 5 | D34: Tampering | E34: High | F34: Group B (Student G, Student H) | G34: Safety tagging — Round 1 | I34: SCADA Server / MTU ↔ RTU (Process WAN link) | J34: High | K34: Attacker on the SCADA–OT path captures legitimate control traffic; messages lack timestamps/nonces/sequence numbers, so valid commands can be replayed undetected. Consequences: unintended breaker operations; energise/de-energise MV bus; overload LV; equipment damage; personnel hazard; grid instability.
A35: C — Master students | B35: 7 | C35: EoP 4 | D35: Elevation of Privilege | E35: High | F35: Group B (Student G, Student H) | G35: Safety tagging — Round 2 | I35: SCADA network | J35: Medium | K35: Attacker exploits a containerised service (e.g. VPN Access server) and escapes to the host OS; can send unauthorised control commands and override operator HMI displays.

Sheet Facilitator notes
A1: Facilitator notes — Safety/HSE tagging (confirmed values + reasoning)
A3: 1. Questions asked for each accepted threat
A4: Q1. Can it create or enable a dangerous physical state? (e.g. wrong switching of breakers, loss of protection, unstable grid)
A5: Q2. Could it harm people, the environment, or critical equipment? (e.g. risk to field technicians or the public, fire, overload, equipment damage)
A6: Then tag the threat:
A7: High — direct risk of injury, major outage, severe equipment damage.
A8: Medium — contributes to unsafe conditions (loss of visibility, delayed response, weakened protection).
A9: Low/None — mainly financial, reputational or confidentiality impact.
A11: 2. Reference architecture (Smart Grid, Purdue model)
A12: Target system zones, top (IT) to bottom (field): Office Network (Router, Workstations & Servers) → DMZ (Firewall, Data Exchange Server) → SCADA Network (SCADA Servers, SCADA HMI, Remote Access via VPN, Firewalls, MTU) → OT Network (Primary Assets, IED, RTU, Switches, Process WAN, Modem, MV Bus, LV Load).
A15: Tagging guideline (good practice, not an absolute rule): as a rule of thumb, the closer a component is to actuating the physical process (MTU, RTU, IED, PLC safety parameters, MV bus, primary assets), the higher its safety impact; IT/DMZ components are usually Low/Medium unless they are a stepping-stone into SCADA/OT. How well it is applied depends on the context the facilitator gives (see sections 3–4).
A38: 3. What we observed when participants assessed safety impact
... A47: Session A — Conference workshop: confirmed Safety/HSE impact
A48: No. | B48: Threat | C48: Device / layer | D48: Safety | E48: Facilitator note
A49: 1 | B49: OT network layer tampering | C49: Process / OT network layer | D49: High | E49: This reaches the OT/process layer directly, so the link to physical process impact is clear.
A50: 2 | B50: Insert a backdoor in the SCADA HMI | C50: SCADA HMI | D50: Medium | E50: The HMI mainly affects supervision and operator trust. It becomes safety-critical if it leads to wrong decisions, but it is not direct actuation by itself.
A51: 3 | B51: VPN key | C51: VPN remote access | D51: Medium | E51: A VPN key is mainly an access path into the SCADA environment. The safety impact depends on what the attacker can reach after that.
A52: 4 | B52: Backdoor (MTU) | C52: MTU | D52: High | E52: The MTU is close to process control, so a backdoor could affect commands, limits, or process behaviour.
A53: 5 | B53: Replaying of commands between RTU and IED | C53: RTU ↔ IED | D53: High | E53: Replayed commands on this path can trigger unintended field actions, so the safety link is direct.
A54: 6 | B54: MTU data tampering | C54: MTU | D54: High | E54: False MTU data can make operators act on an incorrect process state, which may lead to unsafe operation or equipment damage.
A55: 7 | B55: SCADA HMI tampering | C55: SCADA HMI | D55: Medium | E55: This mainly affects what operators see and trust. The safety impact is indirect unless control actions are also affected.
A56: 8 | B56: Displaying old data | C56: MTU | D56: Medium | E56: Stale data can delay detection and response. The risk is serious, but it works through loss of visibility rather than direct control.
A57: 9 | B57: Create information blindness | C57: Field sensors | D57: High | E57: If operators or protection functions lose visibility of part of the process, hazards may go unnoticed.
A58: 10 | B58: MTU safety-parameter tampering | C58: MTU / PLC safety parameters | D58: High | E58: Changing safety parameters directly weakens or bypasses a protection layer.
A59: 11 | B59: Attack via physical device (USB) | C59: HMI workstation | D59: Medium | E59: A USB attack is an entry point. It becomes high only if the compromise reaches process control or safety-related functions.
A61: Session B — CTF group: confirmed Safety/HSE impact (recalibrated)
A62: No. | B62: Threat | C62: Device / layer | D62: Safety | E62: Facilitator note
A63: 1 | B63: Tampering (SCADA Server) | C63: SCADA Server | D63: High | E63: Treated as high if the SCADA server can be manipulated, because it may affect supervision, commands, and the path toward OT control.
A64: 2 | B64: Tampering the DES | C64: Data Exchange Server (DES) | D64: Low–Medium | E64: The DES can mislead operators or disturb data exchange, but the safety link is indirect unless it changes operational decisions or enables deeper SCADA access.
A65: 3 | B65: DMZ Firewall | C65: DMZ Firewall | D65: Medium–High | E65: The firewall itself is not the hazard. The safety impact becomes high if rule changes open a path from IT/DMZ into SCADA or OT.
A66: 4 | B66: Router | C66: Router / Office network | D66: Low–Medium | E66: A good example of the CTF group focusing on familiar IT. An office router is not automatically safety-critical unless it carries SCADA or OT traffic.
A67: 5 | B67: VPN firewall | C67: VPN Firewall / SCADA | D67: Medium | E67: Weak VPN controls make access easier, but the safety impact depends on whether that access can reach SCADA or OT functions.
A68: 6 | B68: MTU | C68: MTU | D68: High | E68: The MTU is close to the control process. Compromise here can influence commands or process coordination.
A69: 7 | B69: Remote access | C69: Remote-access server | D69: Low–Medium | E69: Remote access is an entry point rather than a direct safety mechanism. It becomes more safety-relevant if it gives a credible path into SCADA.
A70: 8 | B70: SCADA HMI | C70: SCADA HMI | D70: High | E70: The HMI can affect what operators see and possibly what they command, creating a clear path to unsafe decisions or control actions.
A71: 9 | B71: Workstation | C71: Office workstation | D71: Medium | E71: An office workstation is not directly safety-critical, but it matters if it becomes a pivot point toward SCADA.
A72: 10 | B72: RTU | C72: RTU / process network | D72: High | E72: The RTU is connected to the physical process, so compromise can directly affect field behaviour.
A73: 11 | B73: Spoofing VPN | C73: VPN | D73: Medium | E73: VPN spoofing is not the safety impact itself. It matters because it may create access to SCADA or OT.
A74: 12 | B74: Credibility | C74: Company web app / JWT | D74: Low | E74: Mainly IT-focused: identity, trust, web security, or confidentiality. There is no clear physical process path.
... A78: 16 | B78: Elevate from the workstations to the SCADA server | C78: Workstation → SCADA Server | D78: High | E78: The key IT-to-OT escalation path. Once the attack reaches the SCADA server, the safety link becomes strong.
...

Sheet STRIDE summary
A1: Threats by STRIDE category and session (auto-counted from 'All Threats')
A3: STRIDE category | B3: Session A — Conf. workshop | C3: Session B — CTF group | D3: Session C — Master* | E3: Total
A4: Tampering | B4: =COUNTIFS('All Threats'!$A$2:$A$60,"A — Conf. workshop",'All Threats'!$D$2:$D$60,$A4) -> 11 | C4: =COUNTIFS('All Threats'!$A$2:$A$60,"B — CTF group",'All Threats'!$D$2:$D$60,$A4) -> 7 | D4: =COUNTIFS('All Threats'!$A$2:$A$60,"C — Master students",'All Threats'!$D$2:$D$60,$A4) -> 3 | E4: =SUM(B4:D4) -> 21
A5: Spoofing | B5: =COUNTIFS('All Threats'!$A$2:$A$60,"A — Conf. workshop",'All Threats'!$D$2:$D$60,$A5) -> 0 | C5: =COUNTIFS('All Threats'!$A$2:$A$60,"B — CTF group",'All Threats'!$D$2:$D$60,$A5) -> 7 | D5: =COUNTIFS('All Threats'!$A$2:$A$60,"C — Master students",'All Threats'!$D$2:$D$60,$A5) -> 0 | E5: =SUM(B5:D5) -> 7
A6: Repudiation | B6: =COUNTIFS('All Threats'!$A$2:$A$60,"A — Conf. workshop",'All Threats'!$D$2:$D$60,$A6) -> 0 | C6: =COUNTIFS('All Threats'!$A$2:$A$60,"B — CTF group",'All Threats'!$D$2:$D$60,$A6) -> 0 | D6: =COUNTIFS('All Threats'!$A$2:$A$60,"C — Master students",'All Threats'!$D$2:$D$60,$A6) -> 0 | E6: =SUM(B6:D6) -> 0
A7: Information Disclosure | B7: =COUNTIFS('All Threats'!$A$2:$A$60,"A — Conf. workshop",'All Threats'!$D$2:$D$60,$A7) -> 0 | C7: =COUNTIFS('All Threats'!$A$2:$A$60,"B — CTF group",'All Threats'!$D$2:$D$60,$A7) -> 0 | D7: =COUNTIFS('All Threats'!$A$2:$A$60,"C — Master students",'All Threats'!$D$2:$D$60,$A7) -> 0 | E7: =SUM(B7:D7) -> 0
A8: Denial of Service | B8: =COUNTIFS('All Threats'!$A$2:$A$60,"A — Conf. workshop",'All Threats'!$D$2:$D$60,$A8) -> 0 | C8: =COUNTIFS('All Threats'!$A$2:$A$60,"B — CTF group",'All Threats'!$D$2:$D$60,$A8) -> 1 | D8: =COUNTIFS('All Threats'!$A$2:$A$60,"C — Master students",'All Threats'!$D$2:$D$60,$A8) -> 0 | E8: =SUM(B8:D8) -> 1
A9: Elevation of Privilege | B9: =COUNTIFS('All Threats'!$A$2:$A$60,"A — Conf. workshop",'All Threats'!$D$2:$D$60,$A9) -> 0 | C9: =COUNTIFS('All Threats'!$A$2:$A$60,"B — CTF group",'All Threats'!$D$2:$D$60,$A9) -> 1 | D9: =COUNTIFS('All Threats'!$A$2:$A$60,"C — Master students",'All Threats'!$D$2:$D$60,$A9) -> 4 | E9: =SUM(B9:D9) -> 5
A10: Total | B10: =SUM(B4:B9) -> 11 | C10: =SUM(C4:C9) -> 16 | D10: =SUM(D4:D9) -> 7 | E10: =SUM(E4:E9) -> 34
A12: * Session C was a safety-tagging activity on two threats (Round 1 = Tampering 5; Round 2 = Elevation of Privilege 4), each assessed by Groups A and B across several device links; its entries are tagging assessments, not independent threats.
